
Running tests... 
----------------------------------------------------------------------
 test_asset_filetype (test_assets.TestAsset) ... ERROR (0.003684)s
 test_asset_method (test_assets.TestAsset) ... ERROR (0.003756)s
 test_asset_uid (test_assets.TestAsset) ... ERROR (0.003998)s
 test_assets_base_query_where_equals_str (test_assets.TestAsset) ... ERROR (0.004326)s
 test_assets_base_query_where_exclude (test_assets.TestAsset) ... ERROR (0.004548)s
 test_assets_base_query_where_exclude_title (test_assets.TestAsset) ... ERROR (0.005590)s
 test_assets_base_query_where_includes (test_assets.TestAsset) ... OK (0.000142)s
 test_assets_base_query_where_is_greater_than (test_assets.TestAsset) ... OK (0.000097)s
 test_assets_base_query_where_is_greater_than_or_equal (test_assets.TestAsset) ... OK (0.000083)s
 test_assets_base_query_where_is_less_than (test_assets.TestAsset) ... OK (0.000078)s
 test_assets_base_query_where_is_less_than_or_equal (test_assets.TestAsset) ... OK (0.000072)s
 test_assets_base_query_where_matches (test_assets.TestAsset) ... OK (0.000071)s
 test_assets_query (test_assets.TestAsset) ... ERROR (0.004005)s

======================================================================
ERROR [0.003684s]: test_assets.TestAsset.test_asset_filetype
----------------------------------------------------------------------
Traceback (most recent call last):
  File "/Users/shaileshmishra/Documents/contentstack/workspace/python/contentstack-python/env/lib/python3.7/site-packages/urllib3/connection.py", line 160, in _new_conn
    (self._dns_host, self.port), self.timeout, **extra_kw
  File "/Users/shaileshmishra/Documents/contentstack/workspace/python/contentstack-python/env/lib/python3.7/site-packages/urllib3/util/connection.py", line 61, in create_connection
    for res in socket.getaddrinfo(host, port, family, socket.SOCK_STREAM):
  File "/usr/local/Cellar/python/3.7.6_1/Frameworks/Python.framework/Versions/3.7/lib/python3.7/socket.py", line 752, in getaddrinfo
    for res in _socket.getaddrinfo(host, port, family, type, proto, flags):
socket.gaierror: [Errno 8] nodename nor servname provided, or not known

During handling of the above exception, another exception occurred:

Traceback (most recent call last):
  File "/Users/shaileshmishra/Documents/contentstack/workspace/python/contentstack-python/env/lib/python3.7/site-packages/urllib3/connectionpool.py", line 677, in urlopen
    chunked=chunked,
  File "/Users/shaileshmishra/Documents/contentstack/workspace/python/contentstack-python/env/lib/python3.7/site-packages/urllib3/connectionpool.py", line 381, in _make_request
    self._validate_conn(conn)
  File "/Users/shaileshmishra/Documents/contentstack/workspace/python/contentstack-python/env/lib/python3.7/site-packages/urllib3/connectionpool.py", line 976, in _validate_conn
    conn.connect()
  File "/Users/shaileshmishra/Documents/contentstack/workspace/python/contentstack-python/env/lib/python3.7/site-packages/urllib3/connection.py", line 308, in connect
    conn = self._new_conn()
  File "/Users/shaileshmishra/Documents/contentstack/workspace/python/contentstack-python/env/lib/python3.7/site-packages/urllib3/connection.py", line 172, in _new_conn
    self, "Failed to establish a new connection: %s" % e
urllib3.exceptions.NewConnectionError: <urllib3.connection.HTTPSConnection object at 0x104c4d510>: Failed to establish a new connection: [Errno 8] nodename nor servname provided, or not known

During handling of the above exception, another exception occurred:

Traceback (most recent call last):
  File "/Users/shaileshmishra/Documents/contentstack/workspace/python/contentstack-python/env/lib/python3.7/site-packages/requests/adapters.py", line 449, in send
    timeout=timeout
  File "/Users/shaileshmishra/Documents/contentstack/workspace/python/contentstack-python/env/lib/python3.7/site-packages/urllib3/connectionpool.py", line 725, in urlopen
    method, url, error=e, _pool=self, _stacktrace=sys.exc_info()[2]
  File "/Users/shaileshmishra/Documents/contentstack/workspace/python/contentstack-python/env/lib/python3.7/site-packages/urllib3/util/retry.py", line 439, in increment
    raise MaxRetryError(_pool, url, error or ResponseError(cause))
urllib3.exceptions.MaxRetryError: HTTPSConnectionPool(host='cdn.contentstack.io', port=443): Max retries exceeded with url: /v3/assets/bltb2291d913f97e9cb?environment=development (Caused by NewConnectionError('<urllib3.connection.HTTPSConnection object at 0x104c4d510>: Failed to establish a new connection: [Errno 8] nodename nor servname provided, or not known'))

During handling of the above exception, another exception occurred:

Traceback (most recent call last):
  File "/Users/shaileshmishra/Documents/contentstack/workspace/python/contentstack-python/tests/test_assets.py", line 31, in test_asset_filetype
    result = self.asset.fetch()
  File "/Users/shaileshmishra/Documents/contentstack/workspace/python/contentstack-python/contentstack/asset.py", line 140, in fetch
    return self.http_instance.get(url)
  File "/Users/shaileshmishra/Documents/contentstack/workspace/python/contentstack-python/contentstack/https_connection.py", line 63, in get
    timeout=self.default_timeout, headers=self.headers)
  File "/Users/shaileshmishra/Documents/contentstack/workspace/python/contentstack-python/env/lib/python3.7/site-packages/requests/api.py", line 76, in get
    return request('get', url, params=params, **kwargs)
  File "/Users/shaileshmishra/Documents/contentstack/workspace/python/contentstack-python/env/lib/python3.7/site-packages/requests/api.py", line 61, in request
    return session.request(method=method, url=url, **kwargs)
  File "/Users/shaileshmishra/Documents/contentstack/workspace/python/contentstack-python/env/lib/python3.7/site-packages/requests/sessions.py", line 530, in request
    resp = self.send(prep, **send_kwargs)
  File "/Users/shaileshmishra/Documents/contentstack/workspace/python/contentstack-python/env/lib/python3.7/site-packages/requests/sessions.py", line 643, in send
    r = adapter.send(request, **kwargs)
  File "/Users/shaileshmishra/Documents/contentstack/workspace/python/contentstack-python/env/lib/python3.7/site-packages/requests/adapters.py", line 516, in send
    raise ConnectionError(e, request=request)
requests.exceptions.ConnectionError: HTTPSConnectionPool(host='cdn.contentstack.io', port=443): Max retries exceeded with url: /v3/assets/bltb2291d913f97e9cb?environment=development (Caused by NewConnectionError('<urllib3.connection.HTTPSConnection object at 0x104c4d510>: Failed to establish a new connection: [Errno 8] nodename nor servname provided, or not known'))

======================================================================
ERROR [0.003756s]: test_assets.TestAsset.test_asset_method
----------------------------------------------------------------------
Traceback (most recent call last):
  File "/Users/shaileshmishra/Documents/contentstack/workspace/python/contentstack-python/env/lib/python3.7/site-packages/urllib3/connection.py", line 160, in _new_conn
    (self._dns_host, self.port), self.timeout, **extra_kw
  File "/Users/shaileshmishra/Documents/contentstack/workspace/python/contentstack-python/env/lib/python3.7/site-packages/urllib3/util/connection.py", line 61, in create_connection
    for res in socket.getaddrinfo(host, port, family, socket.SOCK_STREAM):
  File "/usr/local/Cellar/python/3.7.6_1/Frameworks/Python.framework/Versions/3.7/lib/python3.7/socket.py", line 752, in getaddrinfo
    for res in _socket.getaddrinfo(host, port, family, type, proto, flags):
socket.gaierror: [Errno 8] nodename nor servname provided, or not known

During handling of the above exception, another exception occurred:

Traceback (most recent call last):
  File "/Users/shaileshmishra/Documents/contentstack/workspace/python/contentstack-python/env/lib/python3.7/site-packages/urllib3/connectionpool.py", line 677, in urlopen
    chunked=chunked,
  File "/Users/shaileshmishra/Documents/contentstack/workspace/python/contentstack-python/env/lib/python3.7/site-packages/urllib3/connectionpool.py", line 381, in _make_request
    self._validate_conn(conn)
  File "/Users/shaileshmishra/Documents/contentstack/workspace/python/contentstack-python/env/lib/python3.7/site-packages/urllib3/connectionpool.py", line 976, in _validate_conn
    conn.connect()
  File "/Users/shaileshmishra/Documents/contentstack/workspace/python/contentstack-python/env/lib/python3.7/site-packages/urllib3/connection.py", line 308, in connect
    conn = self._new_conn()
  File "/Users/shaileshmishra/Documents/contentstack/workspace/python/contentstack-python/env/lib/python3.7/site-packages/urllib3/connection.py", line 172, in _new_conn
    self, "Failed to establish a new connection: %s" % e
urllib3.exceptions.NewConnectionError: <urllib3.connection.HTTPSConnection object at 0x104c476d0>: Failed to establish a new connection: [Errno 8] nodename nor servname provided, or not known

During handling of the above exception, another exception occurred:

Traceback (most recent call last):
  File "/Users/shaileshmishra/Documents/contentstack/workspace/python/contentstack-python/env/lib/python3.7/site-packages/requests/adapters.py", line 449, in send
    timeout=timeout
  File "/Users/shaileshmishra/Documents/contentstack/workspace/python/contentstack-python/env/lib/python3.7/site-packages/urllib3/connectionpool.py", line 725, in urlopen
    method, url, error=e, _pool=self, _stacktrace=sys.exc_info()[2]
  File "/Users/shaileshmishra/Documents/contentstack/workspace/python/contentstack-python/env/lib/python3.7/site-packages/urllib3/util/retry.py", line 439, in increment
    raise MaxRetryError(_pool, url, error or ResponseError(cause))
urllib3.exceptions.MaxRetryError: HTTPSConnectionPool(host='cdn.contentstack.io', port=443): Max retries exceeded with url: /v3/assets/bltb2291d913f97e9cb?environment=development&relative_urls=true&include_dimension=true (Caused by NewConnectionError('<urllib3.connection.HTTPSConnection object at 0x104c476d0>: Failed to establish a new connection: [Errno 8] nodename nor servname provided, or not known'))

During handling of the above exception, another exception occurred:

Traceback (most recent call last):
  File "/Users/shaileshmishra/Documents/contentstack/workspace/python/contentstack-python/tests/test_assets.py", line 21, in test_asset_method
    result = self.asset.relative_urls().include_dimension().fetch()
  File "/Users/shaileshmishra/Documents/contentstack/workspace/python/contentstack-python/contentstack/asset.py", line 140, in fetch
    return self.http_instance.get(url)
  File "/Users/shaileshmishra/Documents/contentstack/workspace/python/contentstack-python/contentstack/https_connection.py", line 63, in get
    timeout=self.default_timeout, headers=self.headers)
  File "/Users/shaileshmishra/Documents/contentstack/workspace/python/contentstack-python/env/lib/python3.7/site-packages/requests/api.py", line 76, in get
    return request('get', url, params=params, **kwargs)
  File "/Users/shaileshmishra/Documents/contentstack/workspace/python/contentstack-python/env/lib/python3.7/site-packages/requests/api.py", line 61, in request
    return session.request(method=method, url=url, **kwargs)
  File "/Users/shaileshmishra/Documents/contentstack/workspace/python/contentstack-python/env/lib/python3.7/site-packages/requests/sessions.py", line 530, in request
    resp = self.send(prep, **send_kwargs)
  File "/Users/shaileshmishra/Documents/contentstack/workspace/python/contentstack-python/env/lib/python3.7/site-packages/requests/sessions.py", line 643, in send
    r = adapter.send(request, **kwargs)
  File "/Users/shaileshmishra/Documents/contentstack/workspace/python/contentstack-python/env/lib/python3.7/site-packages/requests/adapters.py", line 516, in send
    raise ConnectionError(e, request=request)
requests.exceptions.ConnectionError: HTTPSConnectionPool(host='cdn.contentstack.io', port=443): Max retries exceeded with url: /v3/assets/bltb2291d913f97e9cb?environment=development&relative_urls=true&include_dimension=true (Caused by NewConnectionError('<urllib3.connection.HTTPSConnection object at 0x104c476d0>: Failed to establish a new connection: [Errno 8] nodename nor servname provided, or not known'))

======================================================================
ERROR [0.003998s]: test_assets.TestAsset.test_asset_uid
----------------------------------------------------------------------
Traceback (most recent call last):
  File "/Users/shaileshmishra/Documents/contentstack/workspace/python/contentstack-python/env/lib/python3.7/site-packages/urllib3/connection.py", line 160, in _new_conn
    (self._dns_host, self.port), self.timeout, **extra_kw
  File "/Users/shaileshmishra/Documents/contentstack/workspace/python/contentstack-python/env/lib/python3.7/site-packages/urllib3/util/connection.py", line 61, in create_connection
    for res in socket.getaddrinfo(host, port, family, socket.SOCK_STREAM):
  File "/usr/local/Cellar/python/3.7.6_1/Frameworks/Python.framework/Versions/3.7/lib/python3.7/socket.py", line 752, in getaddrinfo
    for res in _socket.getaddrinfo(host, port, family, type, proto, flags):
socket.gaierror: [Errno 8] nodename nor servname provided, or not known

During handling of the above exception, another exception occurred:

Traceback (most recent call last):
  File "/Users/shaileshmishra/Documents/contentstack/workspace/python/contentstack-python/env/lib/python3.7/site-packages/urllib3/connectionpool.py", line 677, in urlopen
    chunked=chunked,
  File "/Users/shaileshmishra/Documents/contentstack/workspace/python/contentstack-python/env/lib/python3.7/site-packages/urllib3/connectionpool.py", line 381, in _make_request
    self._validate_conn(conn)
  File "/Users/shaileshmishra/Documents/contentstack/workspace/python/contentstack-python/env/lib/python3.7/site-packages/urllib3/connectionpool.py", line 976, in _validate_conn
    conn.connect()
  File "/Users/shaileshmishra/Documents/contentstack/workspace/python/contentstack-python/env/lib/python3.7/site-packages/urllib3/connection.py", line 308, in connect
    conn = self._new_conn()
  File "/Users/shaileshmishra/Documents/contentstack/workspace/python/contentstack-python/env/lib/python3.7/site-packages/urllib3/connection.py", line 172, in _new_conn
    self, "Failed to establish a new connection: %s" % e
urllib3.exceptions.NewConnectionError: <urllib3.connection.HTTPSConnection object at 0x104c47110>: Failed to establish a new connection: [Errno 8] nodename nor servname provided, or not known

During handling of the above exception, another exception occurred:

Traceback (most recent call last):
  File "/Users/shaileshmishra/Documents/contentstack/workspace/python/contentstack-python/env/lib/python3.7/site-packages/requests/adapters.py", line 449, in send
    timeout=timeout
  File "/Users/shaileshmishra/Documents/contentstack/workspace/python/contentstack-python/env/lib/python3.7/site-packages/urllib3/connectionpool.py", line 725, in urlopen
    method, url, error=e, _pool=self, _stacktrace=sys.exc_info()[2]
  File "/Users/shaileshmishra/Documents/contentstack/workspace/python/contentstack-python/env/lib/python3.7/site-packages/urllib3/util/retry.py", line 439, in increment
    raise MaxRetryError(_pool, url, error or ResponseError(cause))
urllib3.exceptions.MaxRetryError: HTTPSConnectionPool(host='cdn.contentstack.io', port=443): Max retries exceeded with url: /v3/assets/bltb2291d913f97e9cb?environment=development (Caused by NewConnectionError('<urllib3.connection.HTTPSConnection object at 0x104c47110>: Failed to establish a new connection: [Errno 8] nodename nor servname provided, or not known'))

During handling of the above exception, another exception occurred:

Traceback (most recent call last):
  File "/Users/shaileshmishra/Documents/contentstack/workspace/python/contentstack-python/tests/test_assets.py", line 26, in test_asset_uid
    result = self.asset.fetch()
  File "/Users/shaileshmishra/Documents/contentstack/workspace/python/contentstack-python/contentstack/asset.py", line 140, in fetch
    return self.http_instance.get(url)
  File "/Users/shaileshmishra/Documents/contentstack/workspace/python/contentstack-python/contentstack/https_connection.py", line 63, in get
    timeout=self.default_timeout, headers=self.headers)
  File "/Users/shaileshmishra/Documents/contentstack/workspace/python/contentstack-python/env/lib/python3.7/site-packages/requests/api.py", line 76, in get
    return request('get', url, params=params, **kwargs)
  File "/Users/shaileshmishra/Documents/contentstack/workspace/python/contentstack-python/env/lib/python3.7/site-packages/requests/api.py", line 61, in request
    return session.request(method=method, url=url, **kwargs)
  File "/Users/shaileshmishra/Documents/contentstack/workspace/python/contentstack-python/env/lib/python3.7/site-packages/requests/sessions.py", line 530, in request
    resp = self.send(prep, **send_kwargs)
  File "/Users/shaileshmishra/Documents/contentstack/workspace/python/contentstack-python/env/lib/python3.7/site-packages/requests/sessions.py", line 643, in send
    r = adapter.send(request, **kwargs)
  File "/Users/shaileshmishra/Documents/contentstack/workspace/python/contentstack-python/env/lib/python3.7/site-packages/requests/adapters.py", line 516, in send
    raise ConnectionError(e, request=request)
requests.exceptions.ConnectionError: HTTPSConnectionPool(host='cdn.contentstack.io', port=443): Max retries exceeded with url: /v3/assets/bltb2291d913f97e9cb?environment=development (Caused by NewConnectionError('<urllib3.connection.HTTPSConnection object at 0x104c47110>: Failed to establish a new connection: [Errno 8] nodename nor servname provided, or not known'))

======================================================================
ERROR [0.004326s]: test_assets.TestAsset.test_assets_base_query_where_equals_str
----------------------------------------------------------------------
Traceback (most recent call last):
  File "/Users/shaileshmishra/Documents/contentstack/workspace/python/contentstack-python/env/lib/python3.7/site-packages/urllib3/connection.py", line 160, in _new_conn
    (self._dns_host, self.port), self.timeout, **extra_kw
  File "/Users/shaileshmishra/Documents/contentstack/workspace/python/contentstack-python/env/lib/python3.7/site-packages/urllib3/util/connection.py", line 61, in create_connection
    for res in socket.getaddrinfo(host, port, family, socket.SOCK_STREAM):
  File "/usr/local/Cellar/python/3.7.6_1/Frameworks/Python.framework/Versions/3.7/lib/python3.7/socket.py", line 752, in getaddrinfo
    for res in _socket.getaddrinfo(host, port, family, type, proto, flags):
socket.gaierror: [Errno 8] nodename nor servname provided, or not known

During handling of the above exception, another exception occurred:

Traceback (most recent call last):
  File "/Users/shaileshmishra/Documents/contentstack/workspace/python/contentstack-python/env/lib/python3.7/site-packages/urllib3/connectionpool.py", line 677, in urlopen
    chunked=chunked,
  File "/Users/shaileshmishra/Documents/contentstack/workspace/python/contentstack-python/env/lib/python3.7/site-packages/urllib3/connectionpool.py", line 381, in _make_request
    self._validate_conn(conn)
  File "/Users/shaileshmishra/Documents/contentstack/workspace/python/contentstack-python/env/lib/python3.7/site-packages/urllib3/connectionpool.py", line 976, in _validate_conn
    conn.connect()
  File "/Users/shaileshmishra/Documents/contentstack/workspace/python/contentstack-python/env/lib/python3.7/site-packages/urllib3/connection.py", line 308, in connect
    conn = self._new_conn()
  File "/Users/shaileshmishra/Documents/contentstack/workspace/python/contentstack-python/env/lib/python3.7/site-packages/urllib3/connection.py", line 172, in _new_conn
    self, "Failed to establish a new connection: %s" % e
urllib3.exceptions.NewConnectionError: <urllib3.connection.HTTPSConnection object at 0x104c56150>: Failed to establish a new connection: [Errno 8] nodename nor servname provided, or not known

During handling of the above exception, another exception occurred:

Traceback (most recent call last):
  File "/Users/shaileshmishra/Documents/contentstack/workspace/python/contentstack-python/env/lib/python3.7/site-packages/requests/adapters.py", line 449, in send
    timeout=timeout
  File "/Users/shaileshmishra/Documents/contentstack/workspace/python/contentstack-python/env/lib/python3.7/site-packages/urllib3/connectionpool.py", line 725, in urlopen
    method, url, error=e, _pool=self, _stacktrace=sys.exc_info()[2]
  File "/Users/shaileshmishra/Documents/contentstack/workspace/python/contentstack-python/env/lib/python3.7/site-packages/urllib3/util/retry.py", line 439, in increment
    raise MaxRetryError(_pool, url, error or ResponseError(cause))
urllib3.exceptions.MaxRetryError: HTTPSConnectionPool(host='cdn.contentstack.io', port=443): Max retries exceeded with url: /v3/assets?environment=development&query=%22%7B%5C%22title%5C%22%3A+%5C%22images_%281%29.jpg%5C%22%7D%22 (Caused by NewConnectionError('<urllib3.connection.HTTPSConnection object at 0x104c56150>: Failed to establish a new connection: [Errno 8] nodename nor servname provided, or not known'))

During handling of the above exception, another exception occurred:

Traceback (most recent call last):
  File "/Users/shaileshmishra/Documents/contentstack/workspace/python/contentstack-python/tests/test_assets.py", line 52, in test_assets_base_query_where_equals_str
    result = query.find()
  File "/Users/shaileshmishra/Documents/contentstack/workspace/python/contentstack-python/contentstack/assetquery.py", line 119, in find
    return self.http_instance.get(url)
  File "/Users/shaileshmishra/Documents/contentstack/workspace/python/contentstack-python/contentstack/https_connection.py", line 63, in get
    timeout=self.default_timeout, headers=self.headers)
  File "/Users/shaileshmishra/Documents/contentstack/workspace/python/contentstack-python/env/lib/python3.7/site-packages/requests/api.py", line 76, in get
    return request('get', url, params=params, **kwargs)
  File "/Users/shaileshmishra/Documents/contentstack/workspace/python/contentstack-python/env/lib/python3.7/site-packages/requests/api.py", line 61, in request
    return session.request(method=method, url=url, **kwargs)
  File "/Users/shaileshmishra/Documents/contentstack/workspace/python/contentstack-python/env/lib/python3.7/site-packages/requests/sessions.py", line 530, in request
    resp = self.send(prep, **send_kwargs)
  File "/Users/shaileshmishra/Documents/contentstack/workspace/python/contentstack-python/env/lib/python3.7/site-packages/requests/sessions.py", line 643, in send
    r = adapter.send(request, **kwargs)
  File "/Users/shaileshmishra/Documents/contentstack/workspace/python/contentstack-python/env/lib/python3.7/site-packages/requests/adapters.py", line 516, in send
    raise ConnectionError(e, request=request)
requests.exceptions.ConnectionError: HTTPSConnectionPool(host='cdn.contentstack.io', port=443): Max retries exceeded with url: /v3/assets?environment=development&query=%22%7B%5C%22title%5C%22%3A+%5C%22images_%281%29.jpg%5C%22%7D%22 (Caused by NewConnectionError('<urllib3.connection.HTTPSConnection object at 0x104c56150>: Failed to establish a new connection: [Errno 8] nodename nor servname provided, or not known'))

======================================================================
ERROR [0.004548s]: test_assets.TestAsset.test_assets_base_query_where_exclude
----------------------------------------------------------------------
Traceback (most recent call last):
  File "/Users/shaileshmishra/Documents/contentstack/workspace/python/contentstack-python/env/lib/python3.7/site-packages/urllib3/connection.py", line 160, in _new_conn
    (self._dns_host, self.port), self.timeout, **extra_kw
  File "/Users/shaileshmishra/Documents/contentstack/workspace/python/contentstack-python/env/lib/python3.7/site-packages/urllib3/util/connection.py", line 61, in create_connection
    for res in socket.getaddrinfo(host, port, family, socket.SOCK_STREAM):
  File "/usr/local/Cellar/python/3.7.6_1/Frameworks/Python.framework/Versions/3.7/lib/python3.7/socket.py", line 752, in getaddrinfo
    for res in _socket.getaddrinfo(host, port, family, type, proto, flags):
socket.gaierror: [Errno 8] nodename nor servname provided, or not known

During handling of the above exception, another exception occurred:

Traceback (most recent call last):
  File "/Users/shaileshmishra/Documents/contentstack/workspace/python/contentstack-python/env/lib/python3.7/site-packages/urllib3/connectionpool.py", line 677, in urlopen
    chunked=chunked,
  File "/Users/shaileshmishra/Documents/contentstack/workspace/python/contentstack-python/env/lib/python3.7/site-packages/urllib3/connectionpool.py", line 381, in _make_request
    self._validate_conn(conn)
  File "/Users/shaileshmishra/Documents/contentstack/workspace/python/contentstack-python/env/lib/python3.7/site-packages/urllib3/connectionpool.py", line 976, in _validate_conn
    conn.connect()
  File "/Users/shaileshmishra/Documents/contentstack/workspace/python/contentstack-python/env/lib/python3.7/site-packages/urllib3/connection.py", line 308, in connect
    conn = self._new_conn()
  File "/Users/shaileshmishra/Documents/contentstack/workspace/python/contentstack-python/env/lib/python3.7/site-packages/urllib3/connection.py", line 172, in _new_conn
    self, "Failed to establish a new connection: %s" % e
urllib3.exceptions.NewConnectionError: <urllib3.connection.HTTPSConnection object at 0x104c4d0d0>: Failed to establish a new connection: [Errno 8] nodename nor servname provided, or not known

During handling of the above exception, another exception occurred:

Traceback (most recent call last):
  File "/Users/shaileshmishra/Documents/contentstack/workspace/python/contentstack-python/env/lib/python3.7/site-packages/requests/adapters.py", line 449, in send
    timeout=timeout
  File "/Users/shaileshmishra/Documents/contentstack/workspace/python/contentstack-python/env/lib/python3.7/site-packages/urllib3/connectionpool.py", line 725, in urlopen
    method, url, error=e, _pool=self, _stacktrace=sys.exc_info()[2]
  File "/Users/shaileshmishra/Documents/contentstack/workspace/python/contentstack-python/env/lib/python3.7/site-packages/urllib3/util/retry.py", line 439, in increment
    raise MaxRetryError(_pool, url, error or ResponseError(cause))
urllib3.exceptions.MaxRetryError: HTTPSConnectionPool(host='cdn.contentstack.io', port=443): Max retries exceeded with url: /v3/assets?environment=development&query=%22%7B%5C%22file_size%5C%22%3A+%7B%5C%22%24nin%5C%22%3A+%5B5990%2C+3200%5D%7D%7D%22 (Caused by NewConnectionError('<urllib3.connection.HTTPSConnection object at 0x104c4d0d0>: Failed to establish a new connection: [Errno 8] nodename nor servname provided, or not known'))

During handling of the above exception, another exception occurred:

Traceback (most recent call last):
  File "/Users/shaileshmishra/Documents/contentstack/workspace/python/contentstack-python/tests/test_assets.py", line 58, in test_assets_base_query_where_exclude
    result = query.find()
  File "/Users/shaileshmishra/Documents/contentstack/workspace/python/contentstack-python/contentstack/assetquery.py", line 119, in find
    return self.http_instance.get(url)
  File "/Users/shaileshmishra/Documents/contentstack/workspace/python/contentstack-python/contentstack/https_connection.py", line 63, in get
    timeout=self.default_timeout, headers=self.headers)
  File "/Users/shaileshmishra/Documents/contentstack/workspace/python/contentstack-python/env/lib/python3.7/site-packages/requests/api.py", line 76, in get
    return request('get', url, params=params, **kwargs)
  File "/Users/shaileshmishra/Documents/contentstack/workspace/python/contentstack-python/env/lib/python3.7/site-packages/requests/api.py", line 61, in request
    return session.request(method=method, url=url, **kwargs)
  File "/Users/shaileshmishra/Documents/contentstack/workspace/python/contentstack-python/env/lib/python3.7/site-packages/requests/sessions.py", line 530, in request
    resp = self.send(prep, **send_kwargs)
  File "/Users/shaileshmishra/Documents/contentstack/workspace/python/contentstack-python/env/lib/python3.7/site-packages/requests/sessions.py", line 643, in send
    r = adapter.send(request, **kwargs)
  File "/Users/shaileshmishra/Documents/contentstack/workspace/python/contentstack-python/env/lib/python3.7/site-packages/requests/adapters.py", line 516, in send
    raise ConnectionError(e, request=request)
requests.exceptions.ConnectionError: HTTPSConnectionPool(host='cdn.contentstack.io', port=443): Max retries exceeded with url: /v3/assets?environment=development&query=%22%7B%5C%22file_size%5C%22%3A+%7B%5C%22%24nin%5C%22%3A+%5B5990%2C+3200%5D%7D%7D%22 (Caused by NewConnectionError('<urllib3.connection.HTTPSConnection object at 0x104c4d0d0>: Failed to establish a new connection: [Errno 8] nodename nor servname provided, or not known'))

======================================================================
ERROR [0.005590s]: test_assets.TestAsset.test_assets_base_query_where_exclude_title
----------------------------------------------------------------------
Traceback (most recent call last):
  File "/Users/shaileshmishra/Documents/contentstack/workspace/python/contentstack-python/env/lib/python3.7/site-packages/urllib3/connection.py", line 160, in _new_conn
    (self._dns_host, self.port), self.timeout, **extra_kw
  File "/Users/shaileshmishra/Documents/contentstack/workspace/python/contentstack-python/env/lib/python3.7/site-packages/urllib3/util/connection.py", line 61, in create_connection
    for res in socket.getaddrinfo(host, port, family, socket.SOCK_STREAM):
  File "/usr/local/Cellar/python/3.7.6_1/Frameworks/Python.framework/Versions/3.7/lib/python3.7/socket.py", line 752, in getaddrinfo
    for res in _socket.getaddrinfo(host, port, family, type, proto, flags):
socket.gaierror: [Errno 8] nodename nor servname provided, or not known

During handling of the above exception, another exception occurred:

Traceback (most recent call last):
  File "/Users/shaileshmishra/Documents/contentstack/workspace/python/contentstack-python/env/lib/python3.7/site-packages/urllib3/connectionpool.py", line 677, in urlopen
    chunked=chunked,
  File "/Users/shaileshmishra/Documents/contentstack/workspace/python/contentstack-python/env/lib/python3.7/site-packages/urllib3/connectionpool.py", line 381, in _make_request
    self._validate_conn(conn)
  File "/Users/shaileshmishra/Documents/contentstack/workspace/python/contentstack-python/env/lib/python3.7/site-packages/urllib3/connectionpool.py", line 976, in _validate_conn
    conn.connect()
  File "/Users/shaileshmishra/Documents/contentstack/workspace/python/contentstack-python/env/lib/python3.7/site-packages/urllib3/connection.py", line 308, in connect
    conn = self._new_conn()
  File "/Users/shaileshmishra/Documents/contentstack/workspace/python/contentstack-python/env/lib/python3.7/site-packages/urllib3/connection.py", line 172, in _new_conn
    self, "Failed to establish a new connection: %s" % e
urllib3.exceptions.NewConnectionError: <urllib3.connection.HTTPSConnection object at 0x10437b910>: Failed to establish a new connection: [Errno 8] nodename nor servname provided, or not known

During handling of the above exception, another exception occurred:

Traceback (most recent call last):
  File "/Users/shaileshmishra/Documents/contentstack/workspace/python/contentstack-python/env/lib/python3.7/site-packages/requests/adapters.py", line 449, in send
    timeout=timeout
  File "/Users/shaileshmishra/Documents/contentstack/workspace/python/contentstack-python/env/lib/python3.7/site-packages/urllib3/connectionpool.py", line 725, in urlopen
    method, url, error=e, _pool=self, _stacktrace=sys.exc_info()[2]
  File "/Users/shaileshmishra/Documents/contentstack/workspace/python/contentstack-python/env/lib/python3.7/site-packages/urllib3/util/retry.py", line 439, in increment
    raise MaxRetryError(_pool, url, error or ResponseError(cause))
urllib3.exceptions.MaxRetryError: HTTPSConnectionPool(host='cdn.contentstack.io', port=443): Max retries exceeded with url: /v3/assets?environment=development&query=%22%7B%5C%22title%5C%22%3A+%7B%5C%22%24nin%5C%22%3A+%5B%5C%22images_%281%29.jpg%5C%22%5D%7D%7D%22 (Caused by NewConnectionError('<urllib3.connection.HTTPSConnection object at 0x10437b910>: Failed to establish a new connection: [Errno 8] nodename nor servname provided, or not known'))

During handling of the above exception, another exception occurred:

Traceback (most recent call last):
  File "/Users/shaileshmishra/Documents/contentstack/workspace/python/contentstack-python/tests/test_assets.py", line 46, in test_assets_base_query_where_exclude_title
    result = query.find()
  File "/Users/shaileshmishra/Documents/contentstack/workspace/python/contentstack-python/contentstack/assetquery.py", line 119, in find
    return self.http_instance.get(url)
  File "/Users/shaileshmishra/Documents/contentstack/workspace/python/contentstack-python/contentstack/https_connection.py", line 63, in get
    timeout=self.default_timeout, headers=self.headers)
  File "/Users/shaileshmishra/Documents/contentstack/workspace/python/contentstack-python/env/lib/python3.7/site-packages/requests/api.py", line 76, in get
    return request('get', url, params=params, **kwargs)
  File "/Users/shaileshmishra/Documents/contentstack/workspace/python/contentstack-python/env/lib/python3.7/site-packages/requests/api.py", line 61, in request
    return session.request(method=method, url=url, **kwargs)
  File "/Users/shaileshmishra/Documents/contentstack/workspace/python/contentstack-python/env/lib/python3.7/site-packages/requests/sessions.py", line 530, in request
    resp = self.send(prep, **send_kwargs)
  File "/Users/shaileshmishra/Documents/contentstack/workspace/python/contentstack-python/env/lib/python3.7/site-packages/requests/sessions.py", line 643, in send
    r = adapter.send(request, **kwargs)
  File "/Users/shaileshmishra/Documents/contentstack/workspace/python/contentstack-python/env/lib/python3.7/site-packages/requests/adapters.py", line 516, in send
    raise ConnectionError(e, request=request)
requests.exceptions.ConnectionError: HTTPSConnectionPool(host='cdn.contentstack.io', port=443): Max retries exceeded with url: /v3/assets?environment=development&query=%22%7B%5C%22title%5C%22%3A+%7B%5C%22%24nin%5C%22%3A+%5B%5C%22images_%281%29.jpg%5C%22%5D%7D%7D%22 (Caused by NewConnectionError('<urllib3.connection.HTTPSConnection object at 0x10437b910>: Failed to establish a new connection: [Errno 8] nodename nor servname provided, or not known'))

======================================================================
ERROR [0.004005s]: test_assets.TestAsset.test_assets_query
----------------------------------------------------------------------
Traceback (most recent call last):
  File "/Users/shaileshmishra/Documents/contentstack/workspace/python/contentstack-python/env/lib/python3.7/site-packages/urllib3/connection.py", line 160, in _new_conn
    (self._dns_host, self.port), self.timeout, **extra_kw
  File "/Users/shaileshmishra/Documents/contentstack/workspace/python/contentstack-python/env/lib/python3.7/site-packages/urllib3/util/connection.py", line 61, in create_connection
    for res in socket.getaddrinfo(host, port, family, socket.SOCK_STREAM):
  File "/usr/local/Cellar/python/3.7.6_1/Frameworks/Python.framework/Versions/3.7/lib/python3.7/socket.py", line 752, in getaddrinfo
    for res in _socket.getaddrinfo(host, port, family, type, proto, flags):
socket.gaierror: [Errno 8] nodename nor servname provided, or not known

During handling of the above exception, another exception occurred:

Traceback (most recent call last):
  File "/Users/shaileshmishra/Documents/contentstack/workspace/python/contentstack-python/env/lib/python3.7/site-packages/urllib3/connectionpool.py", line 677, in urlopen
    chunked=chunked,
  File "/Users/shaileshmishra/Documents/contentstack/workspace/python/contentstack-python/env/lib/python3.7/site-packages/urllib3/connectionpool.py", line 381, in _make_request
    self._validate_conn(conn)
  File "/Users/shaileshmishra/Documents/contentstack/workspace/python/contentstack-python/env/lib/python3.7/site-packages/urllib3/connectionpool.py", line 976, in _validate_conn
    conn.connect()
  File "/Users/shaileshmishra/Documents/contentstack/workspace/python/contentstack-python/env/lib/python3.7/site-packages/urllib3/connection.py", line 308, in connect
    conn = self._new_conn()
  File "/Users/shaileshmishra/Documents/contentstack/workspace/python/contentstack-python/env/lib/python3.7/site-packages/urllib3/connection.py", line 172, in _new_conn
    self, "Failed to establish a new connection: %s" % e
urllib3.exceptions.NewConnectionError: <urllib3.connection.HTTPSConnection object at 0x1043955d0>: Failed to establish a new connection: [Errno 8] nodename nor servname provided, or not known

During handling of the above exception, another exception occurred:

Traceback (most recent call last):
  File "/Users/shaileshmishra/Documents/contentstack/workspace/python/contentstack-python/env/lib/python3.7/site-packages/requests/adapters.py", line 449, in send
    timeout=timeout
  File "/Users/shaileshmishra/Documents/contentstack/workspace/python/contentstack-python/env/lib/python3.7/site-packages/urllib3/connectionpool.py", line 725, in urlopen
    method, url, error=e, _pool=self, _stacktrace=sys.exc_info()[2]
  File "/Users/shaileshmishra/Documents/contentstack/workspace/python/contentstack-python/env/lib/python3.7/site-packages/urllib3/util/retry.py", line 439, in increment
    raise MaxRetryError(_pool, url, error or ResponseError(cause))
urllib3.exceptions.MaxRetryError: HTTPSConnectionPool(host='cdn.contentstack.io', port=443): Max retries exceeded with url: /v3/assets?environment=development& (Caused by NewConnectionError('<urllib3.connection.HTTPSConnection object at 0x1043955d0>: Failed to establish a new connection: [Errno 8] nodename nor servname provided, or not known'))

During handling of the above exception, another exception occurred:

Traceback (most recent call last):
  File "/Users/shaileshmishra/Documents/contentstack/workspace/python/contentstack-python/tests/test_assets.py", line 40, in test_assets_query
    result = self.asset_query.find()
  File "/Users/shaileshmishra/Documents/contentstack/workspace/python/contentstack-python/contentstack/assetquery.py", line 119, in find
    return self.http_instance.get(url)
  File "/Users/shaileshmishra/Documents/contentstack/workspace/python/contentstack-python/contentstack/https_connection.py", line 63, in get
    timeout=self.default_timeout, headers=self.headers)
  File "/Users/shaileshmishra/Documents/contentstack/workspace/python/contentstack-python/env/lib/python3.7/site-packages/requests/api.py", line 76, in get
    return request('get', url, params=params, **kwargs)
  File "/Users/shaileshmishra/Documents/contentstack/workspace/python/contentstack-python/env/lib/python3.7/site-packages/requests/api.py", line 61, in request
    return session.request(method=method, url=url, **kwargs)
  File "/Users/shaileshmishra/Documents/contentstack/workspace/python/contentstack-python/env/lib/python3.7/site-packages/requests/sessions.py", line 530, in request
    resp = self.send(prep, **send_kwargs)
  File "/Users/shaileshmishra/Documents/contentstack/workspace/python/contentstack-python/env/lib/python3.7/site-packages/requests/sessions.py", line 643, in send
    r = adapter.send(request, **kwargs)
  File "/Users/shaileshmishra/Documents/contentstack/workspace/python/contentstack-python/env/lib/python3.7/site-packages/requests/adapters.py", line 516, in send
    raise ConnectionError(e, request=request)
requests.exceptions.ConnectionError: HTTPSConnectionPool(host='cdn.contentstack.io', port=443): Max retries exceeded with url: /v3/assets?environment=development& (Caused by NewConnectionError('<urllib3.connection.HTTPSConnection object at 0x1043955d0>: Failed to establish a new connection: [Errno 8] nodename nor servname provided, or not known'))

----------------------------------------------------------------------
Ran 13 tests in 0:00:00

FAILED
 (Errors=7)

Generating HTML reports... 
reports/TestResults_test_assets.TestAsset_2020-06-09_13-57-32.html
:00

FAILED
 (Errors=7)

Generating HTML reports... 
reports/TestResults_tests.test_assets.TestAsset_2020-06-09_13-57-32.html
